<robot name="simple_robot"> <!-- robot name- you decide -->
<!-- sequence : link-joint-link-joint-...-link... -->
<!-- units: meters for distance,rad in case of angles -->
<!-- first link called base_link -->
<link name= "base_link">
	<visual>
		<geometry>
			<cylinder length="0.1" radius="0.05"/>
		</geometry>
		<origin rpy="0 0 0" xyz="0 0 0"/> <!-- rpy: roll pitch yaw -> orientation xyz -> position --> 
		<material name= "base_color">
			<color rgba="1 1 0 1"/> 
		</material>
	</visual>

</link>

<!-- first joint-->
<joint name="joint1" type= "revolute"> <!-- types: revolute and prismatic -->
	<parent link="base_link"/>
	<child link="link1"/>
	<origin xyz ="0 0 0.1"/>
	<axis xyz="0 0 1"/>
	<limit effort="300" velocity="0.1" lower="-3.14159" upper="3.14159"/>
	<dynamics damping="50" friction="1"/>

</joint>
<!-- link1-->
<link name= "link1">
	<visual>
		<geometry>
        	<box size="0.3 0.1 0.3"/>
      	</geometry>
		<origin rpy="0 0 0" xyz="0.10 0 0.10"/> <!-- rpy: roll pitch yaw -> orientation xyz -> position --> 
		<material name= "link1_color">
			<color rgba="0 1 0 1"/> 
		</material>
	</visual>

</link>

<!-- second joint-->
<joint name="joint2" type= "revolute"> <!-- types: revolute and prismatic -->
	<parent link="link1"/>
	<child link="link2"/>
	<origin xyz ="0.2 0 0.2"/>
	<axis xyz="0 1 0"/>
	<limit effort="300" velocity="0.1" lower="-3.14159" upper="3.14159"/>
	<dynamics damping="50" friction="1"/>

</joint>

<!-- link2-->
<link name= "link2">
	<visual>
		<geometry>
			<cylinder length="0.4" radius="0.05"/>
		</geometry>
		<origin rpy="0 0 0" xyz="0 0 0.2"/> <!-- rpy: roll pitch yaw -> orientation xyz -> position --> 
		<material name= "link2_color">
			<color rgba="0 0 1 1"/> 
		</material>
	</visual>

</link>

<!-- third joint-->
<joint name="joint3" type= "revolute"> <!-- types: revolute and prismatic -->
	<parent link="link2"/>
	<child link="link3"/>
	<origin xyz ="0 0 0.4"/>
	<axis xyz="0 -1 0"/>
	<limit effort="300" velocity="0.1" lower="-3.14159" upper="3.14159"/>
	<dynamics damping="50" friction="1"/>

</joint>

<!-- link3-->
<link name= "link3">
	<visual>
		<geometry>
			<cylinder length="0.4" radius="0.05"/>
		</geometry>
		<origin rpy="0 1.5707 0" xyz="0.2 0 0"/> <!-- rpy: roll pitch yaw -> orientation xyz -> position --> 
		<material name= "link3_color">
			<color rgba="0 1 1 1"/> 
		</material>
	</visual>

</link>


<!-- link extra-->
<joint name="joint4" type="fixed">
	<parent link="link3"/>
	<child link="link4"/>
	<origin xyz="0.4 0 0"/>
	<axis xyz="1 0 0"/>
	<limit effort="300" velocity="0.1" lower="-3.14159" upper="3.14159"/>
    <dynamics damping="50" friction="1"/>
</joint>
  
<link name="link4">
	<visual>
		<geometry>
			<cylinder length="0.0" radius="0.0"/>
		</geometry>
		<origin rpy="0 0 0" xyz="0 0 0"/> <!-- rpy: roll pitch yaw -> orientation xyz -> position --> 
        <material name= "link4_color">
            <color rgba="0 0 0 1"/> 
        </material>
	</visual>
</link>


</robot>

